Workbook
Name Acustica: TB_Caracteristicas!$P$45
Name Danceability: TB_Caracteristicas!$P$46
Name Energia: TB_Caracteristicas!$P$47
Name high_popularity_spotify_data: Dataset!$A$1:$AC$1687
Name Modern: TB_Distribucion!$D$78
Name SegmentaciónDeDatos_Playlist_genre21: #N/A
Name SegmentaciónDeDatos_playlist_name: #N/A
Name SegmentaciónDeDatos_Playlist_subgenre2: #N/A
Name SegmentaciónDeDatos_Popularidad: #N/A
Name Throwback: TB_Distribucion!$G$92:$H$92
Name Throwbackp: TB_Distribucion!$G$92
Name Total_Pop: TB_Distribucion!$A$56
Name Valence: TB_Caracteristicas!$P$48

Sheet Dataset
A1: energy | B1: tempo | C1: danceability | D1: playlist_genre | E1: loudness | F1: liveness | G1: valence | H1: track_artist | I1: time_signature | J1: speechiness | K1: track_popularity | L1: track_href | M1: uri | N1: track_album_name | O1: playlist_name | P1: analysis_url | Q1: track_id | R1: track_name | S1: track_album_release_date | T1: instrumentalness | U1: track_album_id | V1: mode | W1: key | X1: duration_ms | Y1: acousticness | Z1: id | AA1: playlist_subgenre | AB1: type | AC1: playlist_id
A2: 0.592 | B2: 157969 | C2: 0.521 | D2: pop | E2: -7777 | F2: 0.122 | G2: 0.535 | H2: Lady Gaga, Bruno Mars | I2: 3 | J2: 0.0304 | K2: 100 | L2: https://api.spotify.com/v1/tracks/2plbrEY59IikOBgBGLjaoe | M2: spotify:track:2plbrEY59IikOBgBGLjaoe | N2: Die With A Smile | O2: Today's Top Hits | P2: https://api.spotify.com/v1/audio-analysis/2plbrEY59IikOBgBGLjaoe | Q2: 2plbrEY59IikOBgBGLjaoe | R2: Die With A Smile | S2: 45520 | T2: 0 | U2: 10FLjwfpbxLmW8c25Xyc2N | V2: 0 | W2: 6 | X2: 251668 | Y2: 0.308 | Z2: 2plbrEY59IikOBgBGLjaoe | AA2: mainstream | AB2: audio_features | AC2: 37i9dQZF1DXcBWIGoYBM5M
A3: 0.507 | B3: 104978 | C3: 0.747 | D3: pop | E3: -10171 | F3: 0.117 | G3: 0.438 | H3: Billie Eilish | I3: 4 | J3: 0.0358 | K3: 97 | L3: https://api.spotify.com/v1/tracks/6dOtVTDdiauQNBQEDOtlAB | M3: spotify:track:6dOtVTDdiauQNBQEDOtlAB | N3: HIT ME HARD AND SOFT | O3: Today's Top Hits | P3: https://api.spotify.com/v1/audio-analysis/6dOtVTDdiauQNBQEDOtlAB | Q3: 6dOtVTDdiauQNBQEDOtlAB | R3: BIRDS OF A FEATHER | S3: 45429 | T3: 0.0608 | U3: 7aJuG4TFXa2hmE4z1yxc3n | V3: 1 | W3: 2 | X3: 210373 | Y3: 0.2 | Z3: 6dOtVTDdiauQNBQEDOtlAB | AA3: mainstream | AB3: audio_features | AC3: 37i9dQZF1DXcBWIGoYBM5M
A4: 0.808 | B4: 108548 | C4: 0.554 | D4: pop | E4: -4169 | F4: 0.159 | G4: 0.372 | H4: Gracie Abrams | I4: 4 | J4: 0.0368 | K4: 93 | L4: https://api.spotify.com/v1/tracks/7ne4VBA60CxGM75vw0EYad | M4: spotify:track:7ne4VBA60CxGM75vw0EYad | N4: The Secret of Us (Deluxe) | O4: Today's Top Hits | P4: https://api.spotify.com/v1/audio-analysis/7ne4VBA60CxGM75vw0EYad | Q4: 7ne4VBA60CxGM75vw0EYad | R4: That‚Äôs So True | S4: 45583 | T4: 0 | U4: 0hBRqPYPXhr1RkTDG3n4Mk | V4: 1 | W4: 1 | X4: 166300 | Y4: 0.214 | Z4: 7ne4VBA60CxGM75vw0EYad | AA4: mainstream | AB4: audio_features | AC4: 37i9dQZF1DXcBWIGoYBM5M
A5: 0.91 | B5: 112966 | C5: 0.67 | D5: pop | E5: -4.07 | F5: 0.304 | G5: 0.786 | H5: Sabrina Carpenter | I5: 4 | J5: 0.0634 | K5: 81 | L5: https://api.spotify.com/v1/tracks/1d7Ptw3qYcfpdLNL5REhtJ | M5: spotify:track:1d7Ptw3qYcfpdLNL5REhtJ | N5: Short n' Sweet | O5: Today's Top Hits | P5: https://api.spotify.com/v1/audio-analysis/1d7Ptw3qYcfpdLNL5REhtJ | Q5: 1d7Ptw3qYcfpdLNL5REhtJ | R5: Taste | S5: 45527 | T5: 0 | U5: 4B4Elma4nNDUyl6D5PvQkj | V5: 0 | W5: 0 | X5: 157280 | Y5: 0.0939 | Z5: 1d7Ptw3qYcfpdLNL5REhtJ | AA5: mainstream | AB5: audio_features | AC5: 37i9dQZF1DXcBWIGoYBM5M
A6: 0.783 | B6: 149027 | C6: 0.777 | D6: pop | E6: -4477 | F6: 0.355 | G6: 0.939 | H6: ROS√â, Bruno Mars | I6: 4 | J6: 0.26 | K6: 98 | L6: https://api.spotify.com/v1/tracks/5vNRhkKd0yEAg8suGBpjeY | M6: spotify:track:5vNRhkKd0yEAg8suGBpjeY | N6: APT. | O6: Today's Top Hits | P6: https://api.spotify.com/v1/audio-analysis/5vNRhkKd0yEAg8suGBpjeY | Q6: 5vNRhkKd0yEAg8suGBpjeY | R6: APT. | S6: 45583 | T6: 0 | U6: 2IYQwwgxgOIn7t3iF6ufFD | V6: 0 | W6: 0 | X6: 169917 | Y6: 0.0283 | Z6: 5vNRhkKd0yEAg8suGBpjeY | AA6: mainstream | AB6: audio_features | AC6: 37i9dQZF1DXcBWIGoYBM5M
A7: 0.582 | B7: 116712 | C7: 0.7 | D7: pop | E7: -5.96 | F7: 0.0881 | G7: 0.785 | H7: Chappell Roan | I7: 4 | J7: 0.0356 | K7: 94 | L7: https://api.spotify.com/v1/tracks/0WbMK4wrZ1wFSty9F7FCgu | M7: spotify:track:0WbMK4wrZ1wFSty9F7FCgu | N7: Good Luck, Babe! | O7: Today's Top Hits | P7: https://api.spotify.com/v1/audio-analysis/0WbMK4wrZ1wFSty9F7FCgu | Q7: 0WbMK4wrZ1wFSty9F7FCgu | R7: Good Luck, Babe! | S7: 45387 | T7: 0 | U7: 1WAjjRMfZjEXtB0lQrAw6Q | V7: 0 | W7: 11 | X7: 218424 | Y7: 0.0502 | Z7: 0WbMK4wrZ1wFSty9F7FCgu | AA7: mainstream | AB7: audio_features | AC7: 37i9dQZF1DXcBWIGoYBM5M
A8: 0.561 | B8: 150069 | C8: 0.669 | D8: pop | E8: -6538 | F8: 0.0954 | G8: 0.841 | H8: Addison Rae | I8: 4 | J8: 0.0411 | K8: 88 | L8: https://api.spotify.com/v1/tracks/6MzofobZt2dm0Kf1hTThFz | M8: spotify:track:6MzofobZt2dm0Kf1hTThFz | N8: Diet Pepsi | O8: Today's Top Hits | P8: https://api.spotify.com/v1/audio-analysis/6MzofobZt2dm0Kf1hTThFz | Q8: 6MzofobZt2dm0Kf1hTThFz | R8: Diet Pepsi | S8: 45513 | T8: 0.00962 | U8: 0XA403JTounqFh2owquBXu | V8: 1 | W8: 10 | X8: 169698 | Y8: 0.495 | Z8: 6MzofobZt2dm0Kf1hTThFz | AA8: mainstream | AB8: audio_features | AC8: 37i9dQZF1DXcBWIGoYBM5M
A9: 0.247 | B9: 148101 | C9: 0.467 | D9: pop | E9: -12002 | F9: 0.17 | G9: 0.126 | H9: Billie Eilish | I9: 4 | J9: 0.0431 | K9: 93 | L9: https://api.spotify.com/v1/tracks/3QaPy1KgI7nu9FJEQUgn6h | M9: spotify:track:3QaPy1KgI7nu9FJEQUgn6h | N9: HIT ME HARD AND SOFT | O9: Today's Top Hits | P9: https://api.spotify.com/v1/audio-analysis/3QaPy1KgI7nu9FJEQUgn6h | Q9: 3QaPy1KgI7nu9FJEQUgn6h | R9: WILDFLOWER | S9: 45429 | T9: 0.000271 | U9: 7aJuG4TFXa2hmE4z1yxc3n | V9: 0 | W9: 6 | X9: 261467 | Y9: 0.612 | Z9: 3QaPy1KgI7nu9FJEQUgn6h | AA9: mainstream | AB9: audio_features | AC9: 37i9dQZF1DXcBWIGoYBM5M
A10: 0.416 | B10: 94926 | C10: 0.492 | D10: pop | E10: -10439 | F10: 0.203 | G10: 0.297 | H10: Gigi Perez | I10: 4 | J10: 0.0254 | K10: 71 | L10: https://api.spotify.com/v1/tracks/0UYnhUfnUj5adChuAXvLUB | M10: spotify:track:0UYnhUfnUj5adChuAXvLUB | N10: Sailor Song | O10: Today's Top Hits | P10: https://api.spotify.com/v1/audio-analysis/0UYnhUfnUj5adChuAXvLUB | Q10: 0UYnhUfnUj5adChuAXvLUB | R10: Sailor Song | S10: 45499 | T10: 8.61e-05 | U10: 4DWrYvfGXRE8ko5ZxlIpit | V10: 1 | W10: 11 | X10: 211979 | Y10: 0.686 | Z10: 0UYnhUfnUj5adChuAXvLUB | AA10: mainstream | AB10: audio_features | AC10: 37i9dQZF1DXcBWIGoYBM5M
A11: 0.722 | B11: 119973 | C11: 0.769 | D11: pop | E11: -5485 | F11: 0.111 | G11: 0.57 | H11: The Weeknd, Playboi Carti | I11: 4 | J11: 0.0507 | K11: 92 | L11: https://api.spotify.com/v1/tracks/1Es7AUAhQvapIcoh3qMKDL | M11: spotify:track:1Es7AUAhQvapIcoh3qMKDL | N11: Timeless | O11: Today's Top Hits | P11: https://api.spotify.com/v1/audio-analysis/1Es7AUAhQvapIcoh3qMKDL | Q11: 1Es7AUAhQvapIcoh3qMKDL | R11: Timeless (with Playboi Carti) | S11: 45562 | T11: 2.56e-06 | U11: 2IRxVVqbSbqHJo8Zx50LYn | V11: 0 | W11: 11 | X11: 256000 | Y11: 0.0584 | Z11: 1Es7AUAhQvapIcoh3qMKDL | AA11: mainstream | AB11: audio_features | AC11: 37i9dQZF1DXcBWIGoYBM5M
A12: 0.667 | B12: 130019 | C12: 0.776 | D12: pop | E12: -6622 | F12: 0.0761 | G12: 0.618 | H12: Charli xcx, Billie Eilish | I12: 4 | J12: 0.0983 | K12: 85 | L12: https://api.spotify.com/v1/tracks/3WOhcATHxK2SLNeP5W3v1v | M12: spotify:track:3WOhcATHxK2SLNeP5W3v1v | N12: Guess featuring Billie Eilish | O12: Today's Top Hits | P12: https://api.spotify.com/v1/audio-analysis/3WOhcATHxK2SLNeP5W3v1v | Q12: 3WOhcATHxK2SLNeP5W3v1v | R12: Guess featuring billie eilish | S12: 45505 | T12: 0.3 | U12: 3ThlxfLSy4bfKzxWqmC7VN | V12: 1 | W12: 7 | X12: 145219 | Y12: 0.0146 | Z12: 3WOhcATHxK2SLNeP5W3v1v | AA12: mainstream | AB12: audio_features | AC12: 37i9dQZF1DXcBWIGoYBM5M
A13: 0.586 | B13: 107071 | C13: 0.669 | D13: pop | E13: -6073 | F13: 0.104 | G13: 0.579 | H13: Sabrina Carpenter | I13: 4 | J13: 0.054 | K13: 88 | L13: https://api.spotify.com/v1/tracks/5N3hjp1WNayUPZrA8kJmJP | M13: spotify:track:5N3hjp1WNayUPZrA8kJmJP | N13: Please Please Please | O13: Today's Top Hits | P13: https://api.spotify.com/v1/audio-analysis/5N3hjp1WNayUPZrA8kJmJP | Q13: 5N3hjp1WNayUPZrA8kJmJP | R13: Please Please Please | S13: 45449 | T13: 0 | U13: 5bBaoign62r1i7OV8w7mi9 | V13: 1 | W13: 9 | X13: 186365 | Y13: 0.274 | Z13: 5N3hjp1WNayUPZrA8kJmJP | AA13: mainstream | AB13: audio_features | AC13: 37i9dQZF1DXcBWIGoYBM5M
A14: 0.806 | B14: 104032 | C14: 0.608 | D14: pop | E14: -3443 | F14: 0.191 | G14: 0.587 | H14: Tate McRae | I14: 4 | J14: 0.0486 | K14: 79 | L14: https://api.spotify.com/v1/tracks/1f18HzFpegqvH4ibGJyeMJ | M14: spotify:track:1f18HzFpegqvH4ibGJyeMJ | N14: 2 hands | O14: Today's Top Hits | P14: https://api.spotify.com/v1/audio-analysis/1f18HzFpegqvH4ibGJyeMJ | Q14: 1f18HzFpegqvH4ibGJyeMJ | R14: 2 hands | S14: 45610 | T14: 0 | U14: 2BdJwrx2wMJi7x06wWkUFg | V14: 1 | W14: 1 | X14: 181821 | Y14: 0.121 | Z14: 1f18HzFpegqvH4ibGJyeMJ | AA14: mainstream | AB14: audio_features | AC14: 37i9dQZF1DXcBWIGoYBM5M
A15: 0.709 | B15: 81012 | C15: 0.722 | D15: pop | E15: -4.95 | F15: 0.0804 | G15: 0.604 | H15: Shaboozey | I15: 4 | J15: 0.0273 | K15: 86 | L15: https://api.spotify.com/v1/tracks/2FQrifJ1N335Ljm3TjTVVf | M15: spotify:track:2FQrifJ1N335Ljm3TjTVVf | N15: A Bar Song (Tipsy) | O15: Today's Top Hits | P15: https://api.spotify.com/v1/audio-analysis/2FQrifJ1N335Ljm3TjTVVf | Q15: 2FQrifJ1N335Ljm3TjTVVf | R15: A Bar Song (Tipsy) | S15: 45394 | T15: 0 | U15: 6egBeCLeGITzGSo5VyRjwZ | V15: 1 | W15: 9 | X15: 171292 | Y15: 0.0633 | Z15: 2FQrifJ1N335Ljm3TjTVVf | AA15: mainstream | AB15: audio_features | AC15: 37i9dQZF1DXcBWIGoYBM5M
A16: 0.757 | B16: 139982 | C16: 0.742 | D16: pop | E16: -4981 | F16: 0.305 | G16: 0.957 | H16: Chappell Roan | I16: 4 | J16: 0.0421 | K16: 88 | L16: https://api.spotify.com/v1/tracks/4xdBrk0nFZaP54vvZj0yx7 | M16: spotify:track:4xdBrk0nFZaP54vvZj0yx7 | N16: The Rise and Fall of a Midwest Princess | O16: Today's Top Hits | P16: https://api.spotify.com/v1/audio-analysis/4xdBrk0nFZaP54vvZj0yx7 | Q16: 4xdBrk0nFZaP54vvZj0yx7 | R16: HOT TO GO! | S16: 45191 | T16: 0 | U16: 0EiI8ylL0FmWWpgHVTsZjZ | V16: 1 | W16: 6 | X16: 184841 | Y16: 0.0187 | Z16: 4xdBrk0nFZaP54vvZj0yx7 | AA16: mainstream | AB16: audio_features | AC16: 37i9dQZF1DXcBWIGoYBM5M
A17: 0.917 | B17: 100987 | C17: 0.562 | D17: pop | E17: -2768 | F17: 0.488 | G17: 0.501 | H17: Lady Gaga | I17: 4 | J17: 0.117 | K17: 86 | L17: https://api.spotify.com/v1/tracks/19KlZwqlT3fguP2BeHF1Q1 | M17: spotify:track:19KlZwqlT3fguP2BeHF1Q1 | N17: Disease | O17: Today's Top Hits | P17: https://api.spotify.com/v1/audio-analysis/19KlZwqlT3fguP2BeHF1Q1 | Q17: 19KlZwqlT3fguP2BeHF1Q1 | R17: Disease | S17: 45590 | T17: 0 | U17: 52BWvTRMsPqjHzrbQomgwP | V17: 0 | W17: 11 | X17: 229997 | Y17: 0.0513 | Z17: 19KlZwqlT3fguP2BeHF1Q1 | AA17: mainstream | AB17: audio_features | AC17: 37i9dQZF1DXcBWIGoYBM5M
A18: 0.787 | B18: 109939 | C18: 0.734 | D18: pop | E18: -3951 | F18: 0.312 | G18: 0.672 | H18: LISA | I18: 4 | J18: 0.116 | K18: 82 | L18: https://api.spotify.com/v1/tracks/5G345YEhvleYxQLfYUlEFv | M18: spotify:track:5G345YEhvleYxQLfYUlEFv | N18: Moonlit Floor (Kiss Me) | O18: Today's Top Hits | P18: https://api.spotify.com/v1/audio-analysis/5G345YEhvleYxQLfYUlEFv | Q18: 5G345YEhvleYxQLfYUlEFv | R18: Moonlit Floor (Kiss Me) | S18: 45573 | T18: 0 | U18: 1OGxb1Z5KDBVOwDtyKu8wz | V18: 0 | W18: 5 | X18: 155757 | Y18: 0.126 | Z18: 5G345YEhvleYxQLfYUlEFv | AA18: mainstream | AB18: audio_features | AC18: 37i9dQZF1DXcBWIGoYBM5M
A19: 0.843 | B19: 122064 | C19: 0.619 | D19: pop | E19: -5348 | F19: 0.164 | G19: 0.746 | H19: Morgan Wallen | I19: 4 | J19: 0.0284 | K19: 86 | L19: https://api.spotify.com/v1/tracks/7hR22TOX3RorxJPcsz5Wbo | M19: spotify:track:7hR22TOX3RorxJPcsz5Wbo | N19: Love Somebody | O19: Today's Top Hits | P19: https://api.spotify.com/v1/audio-analysis/7hR22TOX3RorxJPcsz5Wbo | Q19: 7hR22TOX3RorxJPcsz5Wbo | R19: Love Somebody | S19: 45583 | T19: 0.000118 | U19: 0TxewlKVKdpP18dGg279ep | V19: 0 | W19: 5 | X19: 204829 | Y19: 0.00948 | Z19: 7hR22TOX3RorxJPcsz5Wbo | AA19: mainstream | AB19: audio_features | AC19: 37i9dQZF1DXcBWIGoYBM5M
A20: 0.406 | B20: 115.94 | C20: 0.53 | D20: pop | E20: -7507 | F20: 0.133 | G20: 0.338 | H20: Gracie Abrams | I20: 3 | J20: 0.033 | K20: 90 | L20: https://api.spotify.com/v1/tracks/51rfRCiUSvxXlCSCfIztBy | M20: spotify:track:51rfRCiUSvxXlCSCfIztBy | N20: The Secret of Us | O20: Today's Top Hits | P20: https://api.spotify.com/v1/audio-analysis/51rfRCiUSvxXlCSCfIztBy | Q20: 51rfRCiUSvxXlCSCfIztBy | R20: I Love You, I'm Sorry | S20: 45464 | T20: 0 | U20: 56bdWeO40o3WfAD2Lja4dl | V20: 1 | W20: 10 | X20: 157147 | Y20: 0.656 | Z20: 51rfRCiUSvxXlCSCfIztBy | AA20: mainstream | AB20: audio_features | AC20: 37i9dQZF1DXcBWIGoYBM5M
A21: 0.782 | B21: 119992 | C21: 0.727 | D21: pop | E21: -8529 | F21: 0.225 | G21: 0.655 | H21: Adam Port, Stryv, Keinemusik, Orso, Malachiii | I21: 4 | J21: 0.042 | K21: 86 | L21: https://api.spotify.com/v1/tracks/1BJJbSX6muJVF2AK7uH1x4 | M21: spotify:track:1BJJbSX6muJVF2AK7uH1x4 | N21: Move | O21: Today's Top Hits | P21: https://api.spotify.com/v1/audio-analysis/1BJJbSX6muJVF2AK7uH1x4 | Q21: 1BJJbSX6muJVF2AK7uH1x4 | R21: Move | S21: 45450 | T21: 0.336 | U21: 4M8ThNHbNjda2cPwL8XZHS | V21: 0 | W21: 8 | X21: 177599 | Y21: 0.0563 | Z21: 1BJJbSX6muJVF2AK7uH1x4 | AA21: mainstream | AB21: audio_features | AC21: 37i9dQZF1DXcBWIGoYBM5M
A22: 0.812 | B22: 80.09 | C22: 0.505 | D22: pop | E22: -3986 | F22: 0.444 | G22: 0.664 | H22: Tyler, The Creator, GloRilla, Sexyy Red, Lil Wayne | I22: 4 | J22: 0.461 | K22: 88 | L22: https://api.spotify.com/v1/tracks/3tFed7YsjGnIfxeLEQwx3R | M22: spotify:track:3tFed7YsjGnIfxeLEQwx3R | N22: CHROMAKOPIA | O22: Today's Top Hits | P22: https://api.spotify.com/v1/audio-analysis/3tFed7YsjGnIfxeLEQwx3R | Q22: 3tFed7YsjGnIfxeLEQwx3R | R22: Sticky (feat. GloRilla, Sexyy Red & Lil Wayne) | S22: 45593 | T22: 0 | U22: 0U28P0QVB1QRxpqp5IHOlH | V22: 1 | W22: 1 | X22: 255916 | Y22: 0.285 | Z22: 3tFed7YsjGnIfxeLEQwx3R | AA22: mainstream | AB22: audio_features | AC22: 37i9dQZF1DXcBWIGoYBM5M
A23: 0.76 | B23: 103969 | C23: 0.701 | D23: pop | E23: -5478 | F23: 0.185 | G23: 0.69 | H23: Sabrina Carpenter | I23: 4 | J23: 0.0285 | K23: 90 | L23: https://api.spotify.com/v1/tracks/2qSkIjg1o9h3YT9RAgYN75 | M23: spotify:track:2qSkIjg1o9h3YT9RAgYN75 | N23: Espresso | O23: Today's Top Hits | P23: https://api.spotify.com/v1/audio-analysis/2qSkIjg1o9h3YT9RAgYN75 | Q23: 2qSkIjg1o9h3YT9RAgYN75 | R23: Espresso | S23: 45394 | T23: 6.54e-05 | U23: 5quMTd5zeI9yW5UDua8wS4 | V23: 1 | W23: 0 | X23: 175459 | Y23: 0.107 | Z23: 2qSkIjg1o9h3YT9RAgYN75 | AA23: mainstream | AB23: audio_features | AC23: 37i9dQZF1DXcBWIGoYBM5M
A24: 0.725 | B24: 116988 | C24: 0.894 | D24: pop | E24: -4984 | F24: 0.0815 | G24: 0.838 | H24: JENNIE | I24: 4 | J24: 0.0432 | K24: 89 | L24: https://api.spotify.com/v1/tracks/2CspwnypzT7rcWI9RfsoSb | M24: spotify:track:2CspwnypzT7rcWI9RfsoSb | N24: Mantra | O24: Today's Top Hits | P24: https://api.spotify.com/v1/audio-analysis/2CspwnypzT7rcWI9RfsoSb | Q24: 2CspwnypzT7rcWI9RfsoSb | R24: Mantra | S24: 45575 | T24: 1.15e-05 | U24: 3e5tDT1kfaAGx10yOjIDgW | V24: 0 | W24: 10 | X24: 136627 | Y24: 0.00434 | Z24: 2CspwnypzT7rcWI9RfsoSb | AA24: mainstream | AB24: audio_features | AC24: 37i9dQZF1DXcBWIGoYBM5M
A25: 0.563 | B25: 105008 | C25: 0.833 | D25: pop | E25: -5593 | F25: 0.139 | G25: 0.343 | H25: Rauw Alejandro, Bad Bunny | I25: 4 | J25: 0.204 | K25: 82 | L25: https://api.spotify.com/v1/tracks/0l0vcZMU7AOeQmUIREoI2U | M25: spotify:track:0l0vcZMU7AOeQmUIREoI2U | N25: Cosa Nuestra | O25: Today's Top Hits | P25: https://api.spotify.com/v1/audio-analysis/0l0vcZMU7AOeQmUIREoI2U | Q25: 0l0vcZMU7AOeQmUIREoI2U | R25: Qu√© Pasar√≠a... | S25: 45611 | T25: 1.27e-05 | U25: 0aX0UXrHG2ceYIxTQcqJdA | V25: 0 | W25: 4 | X25: 182857 | Y25: 0.528 | Z25: 0l0vcZMU7AOeQmUIREoI2U | AA25: mainstream | AB25: audio_features | AC25: 37i9dQZF1DXcBWIGoYBM5M
A26: 0.628 | B26: 119.98 | C26: 0.757 | D26: pop | E26: -6715 | F26: 0.221 | G26: 0.321 | H26: Don Toliver | I26: 4 | J26: 0.101 | K26: 85 | L26: https://api.spotify.com/v1/tracks/2c7z5oRcPBbqRaBY2mLWcf | M26: spotify:track:2c7z5oRcPBbqRaBY2mLWcf | N26: HARDSTONE PSYCHO | O26: Today's Top Hits | P26: https://api.spotify.com/v1/audio-analysis/2c7z5oRcPBbqRaBY2mLWcf | Q26: 2c7z5oRcPBbqRaBY2mLWcf | R26: NEW DROP | S26: 45457 | T26: 0.0209 | U26: 0Kzb3u6kMnOJOZXYFSk33F | V26: 0 | W26: 4 | X26: 217333 | Y26: 0.189 | Z26: 2c7z5oRcPBbqRaBY2mLWcf | AA26: mainstream | AB26: audio_features | AC26: 37i9dQZF1DXcBWIGoYBM5M
A27: 0.855 | B27: 127986 | C27: 0.638 | D27: pop | E27: -4.86 | F27: 0.245 | G27: 0.731 | H27: Post Malone, Morgan Wallen | I27: 4 | J27: 0.0264 | K27: 84 | L27: https://api.spotify.com/v1/tracks/7221xIgOnuakPdLqT0F3nP | M27: spotify:track:7221xIgOnuakPdLqT0F3nP | N27: I Had Some Help | O27: Today's Top Hits | P27: https://api.spotify.com/v1/audio-analysis/7221xIgOnuakPdLqT0F3nP | Q27: 7221xIgOnuakPdLqT0F3nP | R27: I Had Some Help (Feat. Morgan Wallen) | S27: 45422 | T27: 0 | U27: 1woYXxyyxTQJ0E0AhZE6mj | V27: 1 | W27: 7 | X27: 178206 | Y27: 0.00757 | Z27: 7221xIgOnuakPdLqT0F3nP | AA27: mainstream | AB27: audio_features | AC27: 37i9dQZF1DXcBWIGoYBM5M
A28: 0.62 | B28: 117038 | C28: 0.741 | D28: pop | E28: -5505 | F28: 0.0398 | G28: 0.934 | H28: Hozier | I28: 4 | J28: 0.0412 | K28: 77 | L28: https://api.spotify.com/v1/tracks/4IadxL6BUymXlh8RCJJu7T | M28: spotify:track:4IadxL6BUymXlh8RCJJu7T | N28: Unheard | O28: Today's Top Hits | P28: https://api.spotify.com/v1/audio-analysis/4IadxL6BUymXlh8RCJJu7T | Q28: 4IadxL6BUymXlh8RCJJu7T | R28: Too Sweet | S28: 45373 | T28: 0.000809 | U28: 1KZC0cX0qq6hodR9YVgh9F | V28: 1 | W28: 10 | X28: 251424 | Y28: 0.0295 | Z28: 4IadxL6BUymXlh8RCJJu7T | AA28: mainstream | AB28: audio_features | AC28: 37i9dQZF1DXcBWIGoYBM5M
A29: 0.339 | B29: 97989 | C29: 0.705 | D29: pop | E29: -10612 | F29: 0.12 | G29: 0.457 | H29: The Mar√≠as | I29: 4 | J29: 0.0278 | K29: 84 | L29: https://api.spotify.com/v1/tracks/3siwsiaEoU4Kuuc9WKMUy5 | M29: spotify:track:3siwsiaEoU4Kuuc9WKMUy5 | N29: Submarine | O29: Today's Top Hits | P29: https://api.spotify.com/v1/audio-analysis/3siwsiaEoU4Kuuc9WKMUy5 | Q29: 3siwsiaEoU4Kuuc9WKMUy5 | R29: No One Noticed | S29: 45443 | T29: 0.0814 | U29: 03guxdOi12XJbnvxvxbpwG | V29: 1 | W29: 7 | X29: 236907 | Y29: 0.552 | Z29: 3siwsiaEoU4Kuuc9WKMUy5 | AA29: mainstream | AB29: audio_features | AC29: 37i9dQZF1DXcBWIGoYBM5M
A30: 0.651 | B30: 112648 | C30: 0.694 | D30: pop | E30: -6968 | F30: 0.0787 | G30: 0.471 | H30: Oscar Maydon, Fuerza Regida | I30: 3 | J30: 0.0784 | K30: 93 | L30: https://api.spotify.com/v1/tracks/1cOboCuWYI2osTOfolMRS6 | M30: spotify:track:1cOboCuWYI2osTOfolMRS6 | N30: Tu Boda | O30: Today's Top Hits | P30: https://api.spotify.com/v1/audio-analysis/1cOboCuWYI2osTOfolMRS6 | Q30: 1cOboCuWYI2osTOfolMRS6 | R30: Tu Boda | S30: 45561 | T30: 1.36e-05 | U30: 60cQzWfmdg4hyDXrpW6kOA | V30: 1 | W30: 6 | X30: 225881 | Y30: 0.496 | Z30: 1cOboCuWYI2osTOfolMRS6 | AA30: mainstream | AB30: audio_features | AC30: 37i9dQZF1DXcBWIGoYBM5M
A31: 0.601 | B31: 123994 | C31: 0.635 | D31: pop | E31: -6129 | F31: 0.11 | G31: 0.332 | H31: Myles Smith | I31: 4 | J31: 0.0295 | K31: 88 | L31: https://api.spotify.com/v1/tracks/3Vr3zh0r7ALn8VLqCiRR10 | M31: spotify:track:3Vr3zh0r7ALn8VLqCiRR10 | N31: Stargazing | O31: Today's Top Hits | P31: https://api.spotify.com/v1/audio-analysis/3Vr3zh0r7ALn8VLqCiRR10 | Q31: 3Vr3zh0r7ALn8VLqCiRR10 | R31: Stargazing | S31: 45422 | T31: 0 | U31: 3VNxRarx9HUI5w7DHv0TBj | V31: 0 | W31: 1 | X31: 172533 | Y31: 0.246 | Z31: 3Vr3zh0r7ALn8VLqCiRR10 | AA31: mainstream | AB31: audio_features | AC31: 37i9dQZF1DXcBWIGoYBM5M
A32: 0.691 | B32: 167029 | C32: 0.836 | D32: pop | E32: -4222 | F32: 0.282 | G32: 0.703 | H32: GloRilla, Sexyy Red | I32: 4 | J32: 0.363 | K32: 70 | L32: https://api.spotify.com/v1/tracks/4VI2Y5xg4gYynQqNQNQbTN | M32: spotify:track:4VI2Y5xg4gYynQqNQNQbTN | N32: WHATCHU KNO ABOUT ME (with Sexyy Red) | O32: Today's Top Hits | P32: https://api.spotify.com/v1/audio-analysis/4VI2Y5xg4gYynQqNQNQbTN | Q32: 4VI2Y5xg4gYynQqNQNQbTN | R32: WHATCHU KNO ABOUT ME (with Sexyy Red) | S32: 45575 | T32: 0 | U32: 2PzoiaGTcK3NfnMgHFd7QC | V32: 1 | W32: 1 | X32: 149461 | Y32: 0.00586 | Z32: 4VI2Y5xg4gYynQqNQNQbTN | AA32: mainstream | AB32: audio_features | AC32: 37i9dQZF1DXcBWIGoYBM5M
A33: 0.646 | B33: 115842 | C33: 0.645 | D33: pop | E33: -8334 | F33: 0.074 | G33: 0.295 | H33: Ariana Grande | I33: 4 | J33: 0.0427 | K33: 81 | L33: https://api.spotify.com/v1/tracks/46kspZSY3aKmwQe7O77fCC | M33: spotify:track:46kspZSY3aKmwQe7O77fCC | N33: eternal sunshine | O33: Today's Top Hits | P33: https://api.spotify.com/v1/audio-analysis/46kspZSY3aKmwQe7O77fCC | Q33: 46kspZSY3aKmwQe7O77fCC | R33: we can't be friends (wait for your love) | S33: 45359 | T33: 3.04e-05 | U33: 71PfP4E9roOXAudea1aPGw | V33: 1 | W33: 5 | X33: 228639 | Y33: 0.0615 | Z33: 46kspZSY3aKmwQe7O77fCC | AA33: mainstream | AB33: audio_features | AC33: 37i9dQZF1DXcBWIGoYBM5M
A34: 0.471 | B34: 105029 | C34: 0.472 | D34: pop | E34: -5692 | F34: 0.14 | G34: 0.219 | H34: Benson Boone | I34: 3 | J34: 0.0603 | K34: 85 | L34: https://api.spotify.com/v1/tracks/6tNQ70jh4OwmPGpYy6R2o9 | M34: spotify:track:6tNQ70jh4OwmPGpYy6R2o9 | N34: Beautiful Things | O34: Today's Top Hits | P34: https://api.spotify.com/v1/audio-analysis/6tNQ70jh4OwmPGpYy6R2o9 | Q34: 6tNQ70jh4OwmPGpYy6R2o9 | R34: Beautiful Things | S34: 45309 | T34: 0 | U34: 29aSKB1qPEbN0Qf9OPSQpw | V34: 1 | W34: 10 | X34: 180304 | Y34: 0.151 | Z34: 6tNQ70jh4OwmPGpYy6R2o9 | AA34: mainstream | AB34: audio_features | AC34: 37i9dQZF1DXcBWIGoYBM5M
A35: 0.709 | B35: 194055 | C35: 0.744 | D35: pop | E35: -5778 | F35: 0.0847 | G35: 0.712 | H35: Myke Towers, benny blanco | I35: 4 | J35: 0.284 | K35: 84 | L35: https://api.spotify.com/v1/tracks/0qeIFEGRQqHoaJtLCl0U73 | M35: spotify:track:0qeIFEGRQqHoaJtLCl0U73 | N35: LA PANTERA NEGRA (DELUXE) | O35: Today's Top Hits | P35: https://api.spotify.com/v1/audio-analysis/0qeIFEGRQqHoaJtLCl0U73 | Q35: 0qeIFEGRQqHoaJtLCl0U73 | R35: DEGENERE üëë (feat. benny blanco) | S35: 45582 | T35: 0 | U35: 3pkIK8SI5mcUUjb9jNjx4H | V35: 0 | W35: 6 | X35: 130880 | Y35: 0.0501 | Z35: 0qeIFEGRQqHoaJtLCl0U73 | AA35: mainstream | AB35: audio_features | AC35: 37i9dQZF1DXcBWIGoYBM5M
A36: 0.904 | B36: 167033 | C36: 0.739 | D36: pop | E36: -2655 | F36: 0.0948 | G36: 0.788 | H36: KATSEYE | I36: 4 | J36: 0.0442 | K36: 85 | L36: https://api.spotify.com/v1/tracks/6aJn7Cst74cj4lNIiPRgav | M36: spotify:track:6aJn7Cst74cj4lNIiPRgav | N36: Touch | O36: Today's Top Hits | P36: https://api.spotify.com/v1/audio-analysis/6aJn7Cst74cj4lNIiPRgav | Q36: 6aJn7Cst74cj4lNIiPRgav | R36: Touch | S36: 45499 | T36: 1.03e-05 | U36: 1hjqg3TuQ2YqooaPhxHwdv | V36: 0 | W36: 5 | X36: 129883 | Y36: 0.549 | Z36: 6aJn7Cst74cj4lNIiPRgav | AA36: mainstream | AB36: audio_features | AC36: 37i9dQZF1DXcBWIGoYBM5M
A37: 0.604 | B37: 159.92 | C37: 0.561 | D37: pop | E37: -4409 | F37: 0.104 | G37: 0.242 | H37: Teddy Swims | I37: 3 | J37: 0.0337 | K37: 89 | L37: https://api.spotify.com/v1/tracks/17phhZDn6oGtzMe56NuWvj | M37: spotify:track:17phhZDn6oGtzMe56NuWvj | N37: I've Tried Everything But Therapy (Part 1) | O37: Today's Top Hits | P37: https://api.spotify.com/v1/audio-analysis/17phhZDn6oGtzMe56NuWvj | Q37: 17phhZDn6oGtzMe56NuWvj | R37: Lose Control | S37: 45184 | T37: 1.9e-05 | U37: 7nacKlk586eLRBSIsrk9DB | V37: 1 | W37: 9 | X37: 210689 | Y37: 0.199 | Z37: 17phhZDn6oGtzMe56NuWvj | AA37: mainstream | AB37: audio_features | AC37: 37i9dQZF1DXcBWIGoYBM5M
A38: 0.668 | B38: 90969 | C38: 0.646 | D38: pop | E38: -5203 | F38: 0.212 | G38: 0.64 | H38: Mark Ambor | I38: 4 | J38: 0.0282 | K38: 82 | L38: https://api.spotify.com/v1/tracks/5uQ7de4EWjb3rkcFxyEOpu | M38: spotify:track:5uQ7de4EWjb3rkcFxyEOpu | N38: Belong Together | O38: Today's Top Hits | P38: https://api.spotify.com/v1/audio-analysis/5uQ7de4EWjb3rkcFxyEOpu | Q38: 5uQ7de4EWjb3rkcFxyEOpu | R38: Belong Together | S38: 45338 | T38: 0 | U38: 3PlCMwyq6nuQYtoYproV1o | V38: 1 | W38: 2 | X38: 148318 | Y38: 0.491 | Z38: 5uQ7de4EWjb3rkcFxyEOpu | AA38: mainstream | AB38: audio_features | AC38: 37i9dQZF1DXcBWIGoYBM5M
A39: 0.668 | B39: 128027 | C39: 0.924 | D39: pop | E39: -6795 | F39: 0.0678 | G39: 0.787 | H39: KAROL G | I39: 4 | J39: 0.0469 | K39: 93 | L39: https://api.spotify.com/v1/tracks/6WatFBLVB0x077xWeoVc2k | M39: spotify:track:6WatFBLVB0x077xWeoVc2k | N39: Si Antes Te Hubiera Conocido | O39: Today's Top Hits | P39: https://api.spotify.com/v1/audio-analysis/6WatFBLVB0x077xWeoVc2k | Q39: 6WatFBLVB0x077xWeoVc2k | R39: Si Antes Te Hubiera Conocido | S39: 45464 | T39: 0.000594 | U39: 5ylbxH7EqpsmHZCRuiYewS | V39: 1 | W39: 11 | X39: 195824 | Y39: 0.446 | Z39: 6WatFBLVB0x077xWeoVc2k | AA39: mainstream | AB39: audio_features | AC39: 37i9dQZF1DXcBWIGoYBM5M
A40: 0.454 | B40: 159982 | C40: 0.689 | D40: pop | E40: -7643 | F40: 0.0707 | G40: 0.912 | H40: Djo | I40: 4 | J40: 0.0584 | K40: 89 | L40: https://api.spotify.com/v1/tracks/3qhlB30KknSejmIvZZLjOD | M40: spotify:track:3qhlB30KknSejmIvZZLjOD | N40: DECIDE | O40: Today's Top Hits | P40: https://api.spotify.com/v1/audio-analysis/3qhlB30KknSejmIvZZLjOD | Q40: 3qhlB30KknSejmIvZZLjOD | R40: End of Beginning | S40: 44820 | T40: 0.00259 | U40: 4JDXBZdRPId4devseaAOKH | V40: 1 | W40: 2 | X40: 159246 | Y40: 0.0351 | Z40: 3qhlB30KknSejmIvZZLjOD | AA40: mainstream | AB40: audio_features | AC40: 37i9dQZF1DXcBWIGoYBM5M
...

Sheet TB_Music_Data
A1: Energy | B1: Tempo en BPM | C1: Danceability | D1: Playlist_genre2 | E1: Valence | F1: Track_artist | G1: Track_popularity | H1: Playlist_name | I1: Track_name | J1: Track_album_release_date | K1: Mode | L1: Key | M1: Duration_minutes | N1: Acousticness | O1: Playlist_subgenre2
A2: 0.814 | B2: 93 | C2: 0.683 | D2: =PROPER(Music_Data[[#This Row],[Playlist_genre2]]) -> Afrobeats | E2: 0.758 | F2: Tyla | G2: 78 | H2: Afro Hits | I2: PUSH 2 START | J2: 45576 | K2: 1 | L2: 2 | M2: =LEFT(Music_Data[[#This Row],[Duration_minutes]],3)/60 -> 2.6 | N2: 0.277 | O2: =PROPER(Music_Data[[#This Row],[Playlist_subgenre2]]) -> Nigerian
A3: 0.648 | B3: 93 | C3: 0.737 | D3: =PROPER(Music_Data[[#This Row],[Playlist_genre2]]) -> Afrobeats | E3: 0.746 | F3: Wizkid, Brent Faiyaz | G3: 77 | H3: African Heat | I3: Piece of My Heart (feat. Brent Faiyaz) | J3: 45583 | K3: 1 | L3: 1 | M3: =LEFT(Music_Data[[#This Row],[Duration_minutes]],3)/60 -> 4.3166667 | N3: 0.252 | O3: =PROPER(Music_Data[[#This Row],[Playlist_subgenre2]]) -> African
A4: 0.792 | B4: 113 | C4: 0.749 | D4: =PROPER(Music_Data[[#This Row],[Playlist_genre2]]) -> Afrobeats | E4: 0.903 | F4: Davido, YG Marley | G4: 76 | H4: African Heat | I4: Awuke | J4: 45596 | K4: 1 | L4: 5 | M4: =LEFT(Music_Data[[#This Row],[Duration_minutes]],3)/60 -> 2.8666667 | N4: 0.308 | O4: =PROPER(Music_Data[[#This Row],[Playlist_subgenre2]]) -> African
A5: 0.874 | B5: 118 | C5: 0.774 | D5: =PROPER(Music_Data[[#This Row],[Playlist_genre2]]) -> Afrobeats | E5: 0.927 | F5: Wizkid | G5: 75 | H5: Afro Hits | I5: Kese (Dance) | J5: 45611 | K5: 0 | L5: 5 | M5: =LEFT(Music_Data[[#This Row],[Duration_minutes]],3)/60 -> 2.9 | N5: 0.142 | O5: =PROPER(Music_Data[[#This Row],[Playlist_subgenre2]]) -> Nigerian
A6: 0.634 | B6: 101 | C6: 0.502 | D6: =PROPER(Music_Data[[#This Row],[Playlist_genre2]]) -> Afrobeats | E6: 0.645 | F6: Asake, Wizkid | G6: 72 | H6: African Heat | I6: MMS | J6: 45512 | K6: 0 | L6: 8 | M6: =LEFT(Music_Data[[#This Row],[Duration_minutes]],3)/60 -> 3.65 | N6: 0.677 | O6: =PROPER(Music_Data[[#This Row],[Playlist_subgenre2]]) -> African
A7: 0.683 | B7: 145 | C7: 0.501 | D7: =PROPER(Music_Data[[#This Row],[Playlist_genre2]]) -> Afrobeats | E7: 0.623 | F7: Bnxn, Rema | G7: 71 | H7: Afro Hits | I7: Fi Kan We Kan | J7: 45580 | K7: 0 | L7: 6 | M7: =LEFT(Music_Data[[#This Row],[Duration_minutes]],3)/60 -> 2.6833333 | N7: 0.109 | O7: =PROPER(Music_Data[[#This Row],[Playlist_subgenre2]]) -> Nigerian
A8: 0.719 | B8: 113 | C8: 0.897 | D8: =PROPER(Music_Data[[#This Row],[Playlist_genre2]]) -> Afrobeats | E8: 0.546 | F8: Smur Lee, ODUMODUBLVCK, Shallipopi | G8: 71 | H8: African Heat | I8: JUJU (feat. Shallipopi) | J8: 45526 | K8: 0 | L8: 6 | M8: =LEFT(Music_Data[[#This Row],[Duration_minutes]],3)/60 -> 2.6166667 | N8: 0.116 | O8: =PROPER(Music_Data[[#This Row],[Playlist_subgenre2]]) -> African
A9: 0.819 | B9: 110 | C9: 0.726 | D9: =PROPER(Music_Data[[#This Row],[Playlist_genre2]]) -> Afrobeats | E9: 0.636 | F9: Young Jonn | G9: 70 | H9: African Heat | I9: Stronger | J9: 45394 | K9: 1 | L9: 8 | M9: =LEFT(Music_Data[[#This Row],[Duration_minutes]],3)/60 -> 2.35 | N9: 0.477 | O9: =PROPER(Music_Data[[#This Row],[Playlist_subgenre2]]) -> African
A10: 0.529 | B10: 112 | C10: 0.782 | D10: =PROPER(Music_Data[[#This Row],[Playlist_genre2]]) -> Afrobeats | E10: 0.44 | F10: Ayo Maff | G10: 69 | H10: African Heat | I10: Are you there? | J10: 45519 | K10: 1 | L10: 0 | M10: =LEFT(Music_Data[[#This Row],[Duration_minutes]],3)/60 -> 2.6 | N10: 0.509 | O10: =PROPER(Music_Data[[#This Row],[Playlist_subgenre2]]) -> African
A11: 0.651 | B11: 67 | C11: 0.49 | D11: =PROPER(Music_Data[[#This Row],[Playlist_genre2]]) -> Afrobeats | E11: 0.567 | F11: Ayo Maff, Fireboy DML | G11: 68 | H11: African Heat | I11: Dealer | J11: 45398 | K11: 1 | L11: 11 | M11: =LEFT(Music_Data[[#This Row],[Duration_minutes]],3)/60 -> 3 | N11: 0.714 | O11: =PROPER(Music_Data[[#This Row],[Playlist_subgenre2]]) -> African
A12: 0.812 | B12: 100 | C12: 0.455 | D12: =PROPER(Music_Data[[#This Row],[Playlist_genre2]]) -> Afrobeats | E12: 0.823 | F12: Darkoo, Rema | G12: 68 | H12: Afro Hits | I12: Favourite Girl (with Rema) | J12: 45512 | K12: 1 | L12: 8 | M12: =LEFT(Music_Data[[#This Row],[Duration_minutes]],3)/60 -> 3.0666667 | N12: 0.372 | O12: =PROPER(Music_Data[[#This Row],[Playlist_subgenre2]]) -> Nigerian
A13: 0.52 | B13: 958 | C13: 0.578 | D13: =PROPER(Music_Data[[#This Row],[Playlist_genre2]]) -> Afrobeats | E13: 0.425 | F13: FOLA, Bnxn | G13: 68 | H13: African Heat | I13: alone - Remix | J13: 45569 | K13: 0 | L13: 11 | M13: =LEFT(Music_Data[[#This Row],[Duration_minutes]],3)/60 -> 2.5666667 | N13: 0.554 | O13: =PROPER(Music_Data[[#This Row],[Playlist_subgenre2]]) -> African
... A420: 0.764 | B420: 140 | C420: 0.882 | D420: =PROPER(Music_Data[[#This Row],[Playlist_genre2]]) -> Gaming | E420: 0.886 | F420: Central Cee, Lil Baby | G420: 81 | H420: Top Gaming Tracks | I420: BAND4BAND (feat. Lil Baby) | J420: 45435 | K420: 1 | L420: 11 | M420: =LEFT(Music_Data[[#This Row],[Duration_minutes]],3)/60 -> 2.3333333 | N420: 0.359 | O420: =PROPER(Music_Data[[#This Row],[Playlist_subgenre2]]) -> Modern
A421: 0.62 | B421: 120 | C421: 0.857 | D421: =PROPER(Music_Data[[#This Row],[Playlist_genre2]]) -> Gaming | E421: 0.796 | F421: Charli xcx | G421: 81 | H421: Top Gaming Tracks | I421: 360 | J421: 45450 | K421: 1 | L421: 0 | M421: =LEFT(Music_Data[[#This Row],[Duration_minutes]],3)/60 -> 2.2166667 | N421: 0.646 | O421: =PROPER(Music_Data[[#This Row],[Playlist_subgenre2]]) -> Modern
A422: 0.95 | B422: 150 | C422: 0.673 | D422: =PROPER(Music_Data[[#This Row],[Playlist_genre2]]) -> Gaming | E422: 0.563 | F422: Dimitri Vegas & Like Mike, Tii´sto, Dido, W&W, Dimitri Vegas, Like Mike | G422: 81 | H422: Top Gaming Tracks | I422: Thank You (Not So Bad) | J422: 45261 | K422: 1 | L422: 11 | M422: =LEFT(Music_Data[[#This Row],[Duration_minutes]],3)/60 -> 2.3333333 | N422: 0.0229 | O422: =PROPER(Music_Data[[#This Row],[Playlist_subgenre2]]) -> Modern
A423: 0.887 | B423: 127 | C423: 0.936 | D423: =PROPER(Music_Data[[#This Row],[Playlist_genre2]]) -> Gaming | E423: 0.889 | F423: Eminem | G423: 81 | H423: Top Gaming Tracks | I423: Houdini | J423: 45443 | K423: 0 | L423: 9 | M423: =LEFT(Music_Data[[#This Row],[Duration_minutes]],3)/60 -> 3.7833333 | N423: 0.0292 | O423: =PROPER(Music_Data[[#This Row],[Playlist_subgenre2]]) -> Modern
A424: 0.745 | B424: 165 | C424: 0.808 | D424: =PROPER(Music_Data[[#This Row],[Playlist_genre2]]) -> Gaming | E424: 0.829 | F424: Eminem, Juice WRLD | G424: 81 | H424: Top Gaming Tracks | I424: Godzilla (feat. Juice WRLD) | J424: 43847 | K424: 0 | L424: 10 | M424: =LEFT(Music_Data[[#This Row],[Duration_minutes]],3)/60 -> 3.5 | N424: 0.145 | O424: =PROPER(Music_Data[[#This Row],[Playlist_subgenre2]]) -> Modern
A425: 0.558 | B425: 104 | C425: 0.943 | D425: =PROPER(Music_Data[[#This Row],[Playlist_genre2]]) -> Gaming | E425: 0.606 | F425: Jack Harlow | G425: 81 | H425: Top Gaming Tracks | I425: Lovin On Me | J425: 45240 | K425: 1 | L425: 2 | M425: =LEFT(Music_Data[[#This Row],[Duration_minutes]],3)/60 -> 2.3 | N425: 0.0026 | O425: =PROPER(Music_Data[[#This Row],[Playlist_subgenre2]]) -> Modern
A426: 0.75 | B426: 155 | C426: 0.732 | D426: =PROPER(Music_Data[[#This Row],[Playlist_genre2]]) -> Gaming | E426: 0.401 | F426: Lil Uzi Vert | G426: 81 | H426: Top Gaming Tracks | I426: XO Tour Llif3 | J426: 42972 | K426: 0 | L426: 11 | M426: =LEFT(Music_Data[[#This Row],[Duration_minutes]],3)/60 -> 3.0333333 | N426: 0.00264 | O426: =PROPER(Music_Data[[#This Row],[Playlist_subgenre2]]) -> Modern
A427: 0.632 | B427: 121 | C427: 0.762 | D427: =PROPER(Music_Data[[#This Row],[Playlist_genre2]]) -> Gaming | E427: 0.282 | F427: Lost Frequencies, Calum Scott | G427: 81 | H427: Top Gaming Tracks | I427: Where Are You Now | J427: 45240 | K427: 0 | L427: 6 | M427: =LEFT(Music_Data[[#This Row],[Duration_minutes]],3)/60 -> 2.4833333 | N427: 0.51 | O427: =PROPER(Music_Data[[#This Row],[Playlist_subgenre2]]) -> Modern
A428: 0.761 | B428: 129 | C428: 0.634 | D428: =PROPER(Music_Data[[#This Row],[Playlist_genre2]]) -> Gaming | E428: 0.785 | F428: Marshmello, Kane Brown | G428: 81 | H428: Top Gaming Tracks | I428: Miles On It | J428: 45415 | K428: 1 | L428: 5 | M428: =LEFT(Music_Data[[#This Row],[Duration_minutes]],3)/60 -> 2.8 | N428: 0.00537 | O428: =PROPER(Music_Data[[#This Row],[Playlist_subgenre2]]) -> Modern
A429: 0.586 | B429: 116 | C429: 0.896 | D429: =PROPER(Music_Data[[#This Row],[Playlist_genre2]]) -> Gaming | E429: 0.642 | F429: Roddy Ricch | G429: 81 | H429: Top Gaming Tracks | I429: The Box | J429: 43805 | K429: 0 | L429: 10 | M429: =LEFT(Music_Data[[#This Row],[Duration_minutes]],3)/60 -> 3.2666667 | N429: 0.104 | O429: =PROPER(Music_Data[[#This Row],[Playlist_subgenre2]]) -> Modern
A430: 0.537 | B430: 128 | C430: 0.921 | D430: =PROPER(Music_Data[[#This Row],[Playlist_genre2]]) -> Gaming | E430: 0.711 | F430: XXXTENTACION | G430: 81 | H430: Top Gaming Tracks | I430: Moonlight | J430: 43175 | K430: 0 | L430: 9 | M430: =LEFT(Music_Data[[#This Row],[Duration_minutes]],3)/60 -> 2.25 | N430: 0.556 | O430: =PROPER(Music_Data[[#This Row],[Playlist_subgenre2]]) -> Modern
A431: 0.741 | B431: 120 | C431: 0.771 | D431: =PROPER(Music_Data[[#This Row],[Playlist_genre2]]) -> Gaming | E431: 0.19 | F431: Zerb, The Chainsmokers, Ink | G431: 81 | H431: Top Gaming Tracks | I431: Addicted | J431: 45380 | K431: 0 | L431: 5 | M431: =LEFT(Music_Data[[#This Row],[Duration_minutes]],3)/60 -> 2.5333333 | N431: 0.0245 | O431: =PROPER(Music_Data[[#This Row],[Playlist_subgenre2]]) -> Modern
A432: 0.716 | B432: 910 | C432: 0.701 | D432: =PROPER(Music_Data[[#This Row],[Playlist_genre2]]) -> Gaming | E432: 0.732 | F432: 24kGoldn, iann dior | G432: 80 | H432: Top Gaming Tracks | I432: Mood (feat. iann dior) | J432: 44281 | K432: 0 | L432: 7 | M432: =LEFT(Music_Data[[#This Row],[Duration_minutes]],3)/60 -> 2.3333333 | N432: 0.174 | O432: =PROPER(Music_Data[[#This Row],[Playlist_subgenre2]]) -> Modern
A433: 0.673 | B433: 165 | C433: 0.529 | D433: =PROPER(Music_Data[[#This Row],[Playlist_genre2]]) -> Gaming | E433: 0.366 | F433: Drake, 21 Savage | G433: 80 | H433: Top Gaming Tracks | I433: Jimmy Cooks (feat. 21 Savage) | J433: 44729 | K433: 1 | L433: 0 | M433: =LEFT(Music_Data[[#This Row],[Duration_minutes]],3)/60 -> 3.6333333 | N433: 0.000307 | O433: =PROPER(Music_Data[[#This Row],[Playlist_subgenre2]]) -> Modern
A434: 0.773 | B434: 129 | C434: 0.681 | D434: =PROPER(Music_Data[[#This Row],[Playlist_genre2]]) -> Gaming | E434: 0.504 | F434: Eternxlkz | G434: 80 | H434: Top Gaming Tracks | I434: SLAY! | J434: 45366 | K434: 1 | L434: 1 | M434: =LEFT(Music_Data[[#This Row],[Duration_minutes]],3)/60 -> 1.7833333 | N434: 0.0863 | O434: =PROPER(Music_Data[[#This Row],[Playlist_subgenre2]]) -> Modern
A435: 0.512 | B435: 805 | C435: 0.829 | D435: =PROPER(Music_Data[[#This Row],[Playlist_genre2]]) -> Gaming | E435: 0.638 | F435: Sleepy Hallow | G435: 80 | H435: Top Gaming Tracks | I435: 2055 | J435: 44349 | K435: 0 | L435: 6 | M435: =LEFT(Music_Data[[#This Row],[Duration_minutes]],3)/60 -> 2.05 | N435: 0.492 | O435: =PROPER(Music_Data[[#This Row],[Playlist_subgenre2]]) -> Modern
A436: 0.681 | B436: 139 | C436: 0.918 | D436: =PROPER(Music_Data[[#This Row],[Playlist_genre2]]) -> Gaming | E436: 0.706 | F436: Dave, Central Cee | G436: 79 | H436: Top Gaming Tracks | I436: Sprinter | J436: 45078 | K436: 1 | L436: 1 | M436: =LEFT(Music_Data[[#This Row],[Duration_minutes]],3)/60 -> 3.8166667 | N436: 0.263 | O436: =PROPER(Music_Data[[#This Row],[Playlist_subgenre2]]) -> Modern
A437: 0.797 | B437: 122 | C437: 0.702 | D437: =PROPER(Music_Data[[#This Row],[Playlist_genre2]]) -> Gaming | E437: 0.0356 | F437: Disclosure, Eliza Doolittle, Rivo | G437: 79 | H437: Top Gaming Tracks | I437: You & Me - Rivo Remix | J437: 45282 | K437: 0 | L437: 10 | M437: =LEFT(Music_Data[[#This Row],[Duration_minutes]],3)/60 -> 3.4666667 | N437: 0.583 | O437: =PROPER(Music_Data[[#This Row],[Playlist_subgenre2]]) -> Modern
A438: 0.761 | B438: 146 | C438: 0.62 | D438: =PROPER(Music_Data[[#This Row],[Playlist_genre2]]) -> Gaming | E438: 0.194 | F438: Jungle | G438: 79 | H438: Top Gaming Tracks | I438: Back On 74 | J438: 45149 | K438: 0 | L438: 10 | M438: =LEFT(Music_Data[[#This Row],[Duration_minutes]],3)/60 -> 3.4833333 | N438: 0.207 | O438: =PROPER(Music_Data[[#This Row],[Playlist_subgenre2]]) -> Modern
A439: 0.583 | B439: 116 | C439: 0.709 | D439: =PROPER(Music_Data[[#This Row],[Playlist_genre2]]) -> Gaming | E439: 0.533 | F439: Metro Boomin, Future, Chris Brown | G439: 79 | H439: Top Gaming Tracks | I439: Superhero (Heroes & Villains) [with Future & Chris Brown] | J439: 44897 | K439: 0 | L439: 5 | M439: =LEFT(Music_Data[[#This Row],[Duration_minutes]],3)/60 -> 3.0333333 | N439: 0.138 | O439: =PROPER(Music_Data[[#This Row],[Playlist_subgenre2]]) -> Modern
A440: 0.753 | B440: 127 | C440: 0.671 | D440: =PROPER(Music_Data[[#This Row],[Playlist_genre2]]) -> Gaming | E440: 0.543 | F440: Sonny Fodera, Jazzy, D.O.D | G440: 79 | H440: Top Gaming Tracks | I440: Somedays | J440: 45499 | K440: 0 | L440: 4 | M440: =LEFT(Music_Data[[#This Row],[Duration_minutes]],3)/60 -> 3.45 | N440: 0.019 | O440: =PROPER(Music_Data[[#This Row],[Playlist_subgenre2]]) -> Modern
A441: 0.512 | B441: 960 | C441: 0.803 | D441: =PROPER(Music_Data[[#This Row],[Playlist_genre2]]) -> Gaming | E441: 0.435 | F441: Bryson Tiller | G441: 78 | H441: Top Gaming Tracks | I441: Whatever She Wants | J441: 45335 | K441: 0 | L441: 9 | M441: =LEFT(Music_Data[[#This Row],[Duration_minutes]],3)/60 -> 2.6833333 | N441: 0.128 | O441: =PROPER(Music_Data[[#This Row],[Playlist_subgenre2]]) -> Modern
A442: 0.593 | B442: 120 | C442: 0.565 | D442: =PROPER(Music_Data[[#This Row],[Playlist_genre2]]) -> Gaming | E442: 0.429 | F442: d4vd | G442: 78 | H442: Top Gaming Tracks | I442: Feel It - From The Original Series ‚ÄúInvincible‚Äù | J442: 45379 | K442: 1 | L442: 8 | M442: =LEFT(Music_Data[[#This Row],[Duration_minutes]],3)/60 -> 2.6166667 | N442: 0.0288 | O442: =PROPER(Music_Data[[#This Row],[Playlist_subgenre2]]) -> Modern
A443: 0.567 | B443: 759 | C443: 0.574 | D443: =PROPER(Music_Data[[#This Row],[Playlist_genre2]]) -> Gaming | E443: 0.526 | F443: JID, 21 Savage, Baby Tate | G443: 78 | H443: Top Gaming Tracks | I443: Surround Sound (feat. 21 Savage & Baby Tate) | J443: 44865 | K443: 0 | L443: 7 | M443: =LEFT(Music_Data[[#This Row],[Duration_minutes]],3)/60 -> 3.8166667 | N443: 0.164 | O443: =PROPER(Music_Data[[#This Row],[Playlist_subgenre2]]) -> Modern
A444: 0.643 | B444: 139 | C444: 0.831 | D444: =PROPER(Music_Data[[#This Row],[Playlist_genre2]]) -> Gaming | E444: 0.142 | F444: Kendrick Lamar | G444: 78 | H444: Top Gaming Tracks | I444: euphoria | J444: 45412 | K444: 1 | L444: 1 | M444: =LEFT(Music_Data[[#This Row],[Duration_minutes]],3)/60 -> 6.3833333 | N444: 0.046 | O444: =PROPER(Music_Data[[#This Row],[Playlist_subgenre2]]) -> Modern
A445: 0.452 | B445: 900 | C445: 0.904 | D445: =PROPER(Music_Data[[#This Row],[Playlist_genre2]]) -> Gaming | E445: 0.613 | F445: Tommy Richman | G445: 78 | H445: Top Gaming Tracks | I445: DEVIL IS A LIE | J445: 45457 | K445: 1 | L445: 9 | M445: =LEFT(Music_Data[[#This Row],[Duration_minutes]],3)/60 -> 2.1666667 | N445: 0.174 | O445: =PROPER(Music_Data[[#This Row],[Playlist_subgenre2]]) -> Modern
A446: 0.573 | B446: 140 | C446: 0.911 | D446: =PROPER(Music_Data[[#This Row],[Playlist_genre2]]) -> Gaming | E446: 0.972 | F446: Central Cee | G446: 77 | H446: Top Gaming Tracks | I446: Doja | J446: 44763 | K446: 1 | L446: 6 | M446: =LEFT(Music_Data[[#This Row],[Duration_minutes]],3)/60 -> 16.216667 | N446: 0.38 | O446: =PROPER(Music_Data[[#This Row],[Playlist_subgenre2]]) -> Modern
...

Sheet Dashboard
A1: Analisis de las Caracteristicas y la Distribucion de las canciones mas escuchadas de Spotify
A2: Si Spotify prioriza canciones con alta energía, ritmo bailable y producción digital en sus playlists mas escuchadas, aumentará el engagement de los usuarios, ya que en sus algoritmos y listas editoriales estas características coinciden con las preferencias predominantes de las canciones más escuchadas. | T2: Siguiente Pag
S7: Valence
S9: Acusticness
S12: Danceablilty
S14: Energy
S20: Total Canciones Pop
S22: Total Canciones Modern
S25: Total Canciones Throwback Party

Sheet TB_Caracteristicas
A1: Caracteristicas de las canciones mas escuchadas | J1: SI.ANIDADA
A3: Energy | B3: Tempo | C3: Danceability | D3: Valence | E3: Track_popularity | F3: Mode | G3: Key | H3: Duration_minutes | I3: Acousticness | J3: Popularidad | K3: Track_album_release_date | L3: Variables | M3: Promedios de todas las canciones
A4: 0.592 | B4: 93 | C4: 0.521 | D4: 0.535 | E4: 100 | F4: 0 | G4: 6 | H4: =LEFT(Music_Data[[#This Row],[Duration_minutes]],3)/60 -> 2.6 | I4: 0.308 | J4: =IF(E4>=94,"Muy Popular",IF(E4>=86,"Popular",IF(E4>=78,"No muy popular","Casi nada popular"))) -> Muy Popular | K4: 45576 | L4: Energy | M4: =AVERAGE(TB_Caracteristicas!$A$4:$A$1675) -> 0.6671802 | Q4: Siguiente Pag
A5: 0.592 | B5: 93 | C5: 0.521 | D5: 0.535 | E5: 100 | F5: 0 | G5: 6 | H5: =LEFT(Music_Data[[#This Row],[Duration_minutes]],3)/60 -> 4.3166667 | I5: 0.308 | J5: =IF(E5>=94,"Muy Popular",IF(E5>=86,"Popular",IF(E5>=78,"No muy popular","Casi nada popular"))) -> Muy Popular | K5: 45583 | L5: Danceability | M5: =AVERAGE(TB_Caracteristicas!$C$4:$C$1675) -> 0.65009629
A6: 0.592 | B6: 113 | C6: 0.521 | D6: 0.535 | E6: 100 | F6: 0 | G6: 6 | H6: =LEFT(Music_Data[[#This Row],[Duration_minutes]],3)/60 -> 2.8666667 | I6: 0.308 | J6: =IF(E6>=94,"Muy Popular",IF(E6>=86,"Popular",IF(E6>=78,"No muy popular","Casi nada popular"))) -> Muy Popular | K6: 45596 | L6: Acousticness | M6: =AVERAGE(TB_Caracteristicas!$I$4:$I$1675) -> 0.22162031
A7: 0.783 | B7: 118 | C7: 0.777 | D7: 0.939 | E7: 98 | F7: 0 | G7: 0 | H7: =LEFT(Music_Data[[#This Row],[Duration_minutes]],3)/60 -> 2.9 | I7: 0.0283 | J7: =IF(E7>=94,"Muy Popular",IF(E7>=86,"Popular",IF(E7>=78,"No muy popular","Casi nada popular"))) -> Muy Popular | K7: 45611 | L7: Valence | M7: =AVERAGE(TB_Caracteristicas!$D$4:$D$1675) -> 0.52491316
A8: 0.783 | B8: 101 | C8: 0.777 | D8: 0.939 | E8: 98 | F8: 0 | G8: 0 | H8: =LEFT(Music_Data[[#This Row],[Duration_minutes]],3)/60 -> 3.65 | I8: 0.0283 | J8: =IF(E8>=94,"Muy Popular",IF(E8>=86,"Popular",IF(E8>=78,"No muy popular","Casi nada popular"))) -> Muy Popular | K8: 45512
A9: 0.507 | B9: 145 | C9: 0.747 | D9: 0.438 | E9: 97 | F9: 1 | G9: 2 | H9: =LEFT(Music_Data[[#This Row],[Duration_minutes]],3)/60 -> 2.6833333 | I9: 0.2 | J9: =IF(E9>=94,"Muy Popular",IF(E9>=86,"Popular",IF(E9>=78,"No muy popular","Casi nada popular"))) -> Muy Popular | K9: 45580 | L9: Tonalidad | M9: Suma de Track_popularity
A10: 0.507 | B10: 113 | C10: 0.747 | D10: 0.438 | E10: 97 | F10: 1 | G10: 2 | H10: =LEFT(Music_Data[[#This Row],[Duration_minutes]],3)/60 -> 2.6166667 | I10: 0.2 | J10: =IF(E10>=94,"Muy Popular",IF(E10>=86,"Popular",IF(E10>=78,"No muy popular","Casi nada popular"))) -> Muy Popular | K10: 45526 | L10: 0 | M10: 11598
A11: 0.507 | B11: 110 | C11: 0.747 | D11: 0.438 | E11: 97 | F11: 1 | G11: 2 | H11: =LEFT(Music_Data[[#This Row],[Duration_minutes]],3)/60 -> 2.35 | I11: 0.2 | J11: =IF(E11>=94,"Muy Popular",IF(E11>=86,"Popular",IF(E11>=78,"No muy popular","Casi nada popular"))) -> Muy Popular | K11: 45394 | L11: 1 | M11: 17104
A12: 0.582 | B12: 112 | C12: 0.7 | D12: 0.785 | E12: 94 | F12: 0 | G12: 11 | H12: =LEFT(Music_Data[[#This Row],[Duration_minutes]],3)/60 -> 2.6 | I12: 0.0502 | J12: =IF(E12>=94,"Muy Popular",IF(E12>=86,"Popular",IF(E12>=78,"No muy popular","Casi nada popular"))) -> Muy Popular | K12: 45519 | L12: 2 | M12: 11572
A13: 0.582 | B13: 67 | C13: 0.7 | D13: 0.785 | E13: 94 | F13: 0 | G13: 11 | H13: =LEFT(Music_Data[[#This Row],[Duration_minutes]],3)/60 -> 3 | I13: 0.0502 | J13: =IF(E13>=94,"Muy Popular",IF(E13>=86,"Popular",IF(E13>=78,"No muy popular","Casi nada popular"))) -> Muy Popular | K13: 45398 | L13: 3 | M13: 4062
A14: 0.582 | B14: 100 | C14: 0.7 | D14: 0.785 | E14: 94 | F14: 0 | G14: 11 | H14: =LEFT(Music_Data[[#This Row],[Duration_minutes]],3)/60 -> 3.0666667 | I14: 0.0502 | J14: =IF(E14>=94,"Muy Popular",IF(E14>=86,"Popular",IF(E14>=78,"No muy popular","Casi nada popular"))) -> Muy Popular | K14: 45512 | L14: 4 | M14: 9262
A15: 0.808 | B15: 958 | C15: 0.554 | D15: 0.372 | E15: 93 | F15: 1 | G15: 1 | H15: =LEFT(Music_Data[[#This Row],[Duration_minutes]],3)/60 -> 2.5666667 | I15: 0.214 | J15: =IF(E15>=94,"Muy Popular",IF(E15>=86,"Popular",IF(E15>=78,"No muy popular","Casi nada popular"))) -> Popular | K15: 45569 | L15: 5 | M15: 11538
A16: 0.247 | B16: 197 | C16: 0.467 | D16: 0.126 | E16: 93 | F16: 0 | G16: 6 | H16: =LEFT(Music_Data[[#This Row],[Duration_minutes]],3)/60 -> 3.2166667 | I16: 0.612 | J16: =IF(E16>=94,"Muy Popular",IF(E16>=86,"Popular",IF(E16>=78,"No muy popular","Casi nada popular"))) -> Popular | K16: 45532 | L16: 6 | M16: 10263
A17: 0.651 | B17: 147 | C17: 0.694 | D17: 0.471 | E17: 93 | F17: 1 | G17: 6 | H17: =LEFT(Music_Data[[#This Row],[Duration_minutes]],3)/60 -> 2.2833333 | I17: 0.496 | J17: =IF(E17>=94,"Muy Popular",IF(E17>=86,"Popular",IF(E17>=78,"No muy popular","Casi nada popular"))) -> Popular | K17: 45483 | L17: 7 | M17: 11475
A18: 0.668 | B18: 171 | C18: 0.924 | D18: 0.787 | E18: 93 | F18: 1 | G18: 11 | H18: =LEFT(Music_Data[[#This Row],[Duration_minutes]],3)/60 -> 2.1833333 | I18: 0.446 | J18: =IF(E18>=94,"Muy Popular",IF(E18>=86,"Popular",IF(E18>=78,"No muy popular","Casi nada popular"))) -> Popular | K18: 45478 | L18: 8 | M18: 8831
A19: 0.651 | B19: 113 | C19: 0.694 | D19: 0.471 | E19: 93 | F19: 1 | G19: 6 | H19: =LEFT(Music_Data[[#This Row],[Duration_minutes]],3)/60 -> 2.2833333 | I19: 0.496 | J19: =IF(E19>=94,"Muy Popular",IF(E19>=86,"Popular",IF(E19>=78,"No muy popular","Casi nada popular"))) -> Popular | K19: 45184 | L19: 9 | M19: 10210
A20: 0.668 | B20: 944 | C20: 0.924 | D20: 0.787 | E20: 93 | F20: 1 | G20: 11 | H20: =LEFT(Music_Data[[#This Row],[Duration_minutes]],3)/60 -> 4.8333333 | I20: 0.446 | J20: =IF(E20>=94,"Muy Popular",IF(E20>=86,"Popular",IF(E20>=78,"No muy popular","Casi nada popular"))) -> Popular | K20: 42895 | L20: 10 | M20: 8425
A21: 0.808 | B21: 102 | C21: 0.554 | D21: 0.372 | E21: 93 | F21: 1 | G21: 1 | H21: =LEFT(Music_Data[[#This Row],[Duration_minutes]],3)/60 -> 3.7833333 | I21: 0.214 | J21: =IF(E21>=94,"Muy Popular",IF(E21>=86,"Popular",IF(E21>=78,"No muy popular","Casi nada popular"))) -> Popular | K21: 36717 | L21: 11 | M21: 13124
A22: 0.413 | B22: 102 | C22: 0.494 | D22: 0.273 | E22: 93 | F22: 1 | G22: 11 | H22: =LEFT(Music_Data[[#This Row],[Duration_minutes]],3)/60 -> 3.3 | I22: 0.682 | J22: =IF(E22>=94,"Muy Popular",IF(E22>=86,"Popular",IF(E22>=78,"No muy popular","Casi nada popular"))) -> Popular | K22: 43910 | L22: Total general | M22: 127464
A23: 0.907 | B23: 113 | C23: 0.674 | D23: 0.721 | E23: 93 | F23: 1 | G23: 3 | H23: =LEFT(Music_Data[[#This Row],[Duration_minutes]],3)/60 -> 3.9333333 | I23: 0.101 | J23: =IF(E23>=94,"Muy Popular",IF(E23>=86,"Popular",IF(E23>=78,"No muy popular","Casi nada popular"))) -> Popular | K23: 41275
A24: 0.651 | B24: 130 | C24: 0.694 | D24: 0.471 | E24: 93 | F24: 1 | G24: 6 | H24: =LEFT(Music_Data[[#This Row],[Duration_minutes]],3)/60 -> 3.9833333 | I24: 0.496 | J24: =IF(E24>=94,"Muy Popular",IF(E24>=86,"Popular",IF(E24>=78,"No muy popular","Casi nada popular"))) -> Popular | K24: 44036 | L24: *Teniendo en cuenta que los valores del 0 al 11 corresponden a la tonalidad de la canacion , 0 siendo Do y 11 Si
A25: 0.247 | B25: 833 | C25: 0.467 | D25: 0.126 | E25: 93 | F25: 0 | G25: 6 | H25: =LEFT(Music_Data[[#This Row],[Duration_minutes]],3)/60 -> 3.15 | I25: 0.612 | J25: =IF(E25>=94,"Muy Popular",IF(E25>=86,"Popular",IF(E25>=78,"No muy popular","Casi nada popular"))) -> Popular | K25: 44680
A26: 0.668 | B26: 129 | C26: 0.924 | D26: 0.787 | E26: 93 | F26: 1 | G26: 11 | H26: =LEFT(Music_Data[[#This Row],[Duration_minutes]],3)/60 -> 4.0166667 | I26: 0.446 | J26: =IF(E26>=94,"Muy Popular",IF(E26>=86,"Popular",IF(E26>=78,"No muy popular","Casi nada popular"))) -> Popular | K26: 41901
A27: 0.413 | B27: 137 | C27: 0.494 | D27: 0.273 | E27: 93 | F27: 1 | G27: 11 | H27: =LEFT(Music_Data[[#This Row],[Duration_minutes]],3)/60 -> 2.6833333 | I27: 0.682 | J27: =IF(E27>=94,"Muy Popular",IF(E27>=86,"Popular",IF(E27>=78,"No muy popular","Casi nada popular"))) -> Popular | K27: 43565 | L27: Modos | M27: Suma de Track_popularity
A28: 0.668 | B28: 107 | C28: 0.924 | D28: 0.787 | E28: 93 | F28: 1 | G28: 11 | H28: =LEFT(Music_Data[[#This Row],[Duration_minutes]],3)/60 -> 5.85 | I28: 0.446 | J28: =IF(E28>=94,"Muy Popular",IF(E28>=86,"Popular",IF(E28>=78,"No muy popular","Casi nada popular"))) -> Popular | K28: 41640 | L28: 0 | M28: 53620
A29: 0.722 | B29: 148 | C29: 0.769 | D29: 0.57 | E29: 92 | F29: 0 | G29: 11 | H29: =LEFT(Music_Data[[#This Row],[Duration_minutes]],3)/60 -> 3.0333333 | I29: 0.0584 | J29: =IF(E29>=94,"Muy Popular",IF(E29>=86,"Popular",IF(E29>=78,"No muy popular","Casi nada popular"))) -> Popular | K29: 44659 | L29: 1 | M29: 73844
A30: 0.756 | B30: 139 | C30: 0.66 | D30: 0.838 | E30: 92 | F30: 0 | G30: 0 | H30: =LEFT(Music_Data[[#This Row],[Duration_minutes]],3)/60 -> 3.8166667 | I30: 0.00289 | J30: =IF(E30>=94,"Muy Popular",IF(E30>=86,"Popular",IF(E30>=78,"No muy popular","Casi nada popular"))) -> Popular | K30: 45078 | L30: Total general | M30: 127464
A31: 0.722 | B31: 201 | C31: 0.769 | D31: 0.57 | E31: 92 | F31: 0 | G31: 11 | H31: =LEFT(Music_Data[[#This Row],[Duration_minutes]],3)/60 -> 4.5166667 | I31: 0.0584 | J31: =IF(E31>=94,"Muy Popular",IF(E31>=86,"Popular",IF(E31>=78,"No muy popular","Casi nada popular"))) -> Popular | K31: 44274
A32: 0.756 | B32: 103 | C32: 0.66 | D32: 0.838 | E32: 92 | F32: 0 | G32: 0 | H32: =LEFT(Music_Data[[#This Row],[Duration_minutes]],3)/60 -> 5.65 | I32: 0.00289 | J32: =IF(E32>=94,"Muy Popular",IF(E32>=86,"Popular",IF(E32>=78,"No muy popular","Casi nada popular"))) -> Popular | K32: 45009
A33: 0.722 | B33: 117 | C33: 0.769 | D33: 0.57 | E33: 92 | F33: 0 | G33: 11 | H33: =LEFT(Music_Data[[#This Row],[Duration_minutes]],3)/60 -> 4.2833333 | I33: 0.0584 | J33: =IF(E33>=94,"Muy Popular",IF(E33>=86,"Popular",IF(E33>=78,"No muy popular","Casi nada popular"))) -> Popular | K33: 42881
A34: 0.722 | B34: 961 | C34: 0.769 | D34: 0.57 | E34: 92 | F34: 0 | G34: 11 | H34: =LEFT(Music_Data[[#This Row],[Duration_minutes]],3)/60 -> 3.5166667 | I34: 0.0584 | J34: =IF(E34>=94,"Muy Popular",IF(E34>=86,"Popular",IF(E34>=78,"No muy popular","Casi nada popular"))) -> Popular | K34: 44827
A35: 0.406 | B35: 121 | C35: 0.53 | D35: 0.338 | E35: 90 | F35: 1 | G35: 10 | H35: =LEFT(Music_Data[[#This Row],[Duration_minutes]],3)/60 -> 3.8166667 | I35: 0.656 | J35: =IF(E35>=94,"Muy Popular",IF(E35>=86,"Popular",IF(E35>=78,"No muy popular","Casi nada popular"))) -> Popular | K35: 41901
A36: 0.76 | B36: 135 | C36: 0.701 | D36: 0.69 | E36: 90 | F36: 1 | G36: 0 | H36: =LEFT(Music_Data[[#This Row],[Duration_minutes]],3)/60 -> 3.2166667 | I36: 0.107 | J36: =IF(E36>=94,"Muy Popular",IF(E36>=86,"Popular",IF(E36>=78,"No muy popular","Casi nada popular"))) -> Popular | K36: 43399
A37: 0.76 | B37: 932 | C37: 0.701 | D37: 0.69 | E37: 90 | F37: 1 | G37: 0 | H37: =LEFT(Music_Data[[#This Row],[Duration_minutes]],3)/60 -> 4.3166667 | I37: 0.107 | J37: =IF(E37>=94,"Muy Popular",IF(E37>=86,"Popular",IF(E37>=78,"No muy popular","Casi nada popular"))) -> Popular | K37: 45583
A38: 0.406 | B38: 133 | C38: 0.53 | D38: 0.338 | E38: 90 | F38: 1 | G38: 10 | H38: =LEFT(Music_Data[[#This Row],[Duration_minutes]],3)/60 -> 2.95 | I38: 0.656 | J38: =IF(E38>=94,"Muy Popular",IF(E38>=86,"Popular",IF(E38>=78,"No muy popular","Casi nada popular"))) -> Popular | K38: 44687
A39: 0.807 | B39: 723 | C39: 0.612 | D39: 0.398 | E39: 90 | F39: 1 | G39: 10 | H39: =LEFT(Music_Data[[#This Row],[Duration_minutes]],3)/60 -> 3.9 | I39: 0.0495 | J39: =IF(E39>=94,"Muy Popular",IF(E39>=86,"Popular",IF(E39>=78,"No muy popular","Casi nada popular"))) -> Popular | K39: 44407
A40: 0.417 | B40: 159 | C40: 0.464 | D40: 0.479 | E40: 90 | F40: 0 | G40: 0 | H40: =LEFT(Music_Data[[#This Row],[Duration_minutes]],3)/60 -> 4.8166667 | I40: 0.136 | J40: =IF(E40>=94,"Muy Popular",IF(E40>=86,"Popular",IF(E40>=78,"No muy popular","Casi nada popular"))) -> Popular | K40: 40102
A41: 0.559 | B41: 779 | C41: 0.558 | D41: 0.62 | E41: 90 | F41: 1 | G41: 6 | H41: =LEFT(Music_Data[[#This Row],[Duration_minutes]],3)/60 -> 2.95 | I41: 0.371 | J41: =IF(E41>=94,"Muy Popular",IF(E41>=86,"Popular",IF(E41>=78,"No muy popular","Casi nada popular"))) -> Popular | K41: 45177
...

Sheet TB_Distribucion
A1: Criterios de Distribucion | I1: Siguiente Pag
A2: Como se buscan las canciones mas escuchadas en Spotify ?
A3: Por Genero, Subgenero y Playlists
A4: Cuantos Generos musicales hay ? | C4: =COUNT(Anexas!$N7:$N34) -> 28 | D4: Cuantos Subgeneros musicales hay ? | F4: =COUNT(Anexas!$A2:$A54) -> 53 | G4: Cuantas Playlists de musica hay ? | I4: =COUNT(Playlists[ID_playlist_name]) -> 73
A5: Cual es el Genero mas escuchado ? | C5: =_xlfn.XLOOKUP(357,Generos[Cantidad de Canciones por genero],Generos[playlist_genre]) -> #N/A | D5: Cual es el Subgenero mas escuchado? | F5: =_xlfn.XLOOKUP(356,Subgenero[Canciones por subgenero],Subgenero[playlist_subgenre]) -> Modern | G5: Cual es la Playlist mas escuchada? | I5: =_xlfn.XLOOKUP(150,Playlists[Canciones por Playlist],Playlists[playlist_name]) -> Throwback Party
A6: Cuantas canciones son del el Genero mas escuchado? | C6: =MAX(Generos[Cantidad de Canciones por genero]) -> #REF! | D6: Cuantas canciones son del Subgenero mas escuchado? | F6: =MAX(Subgenero[Canciones por subgenero]) -> 356 | G6: Cuantas canciones son de la Playlist mas escuchada ? | I6: =MAX(Playlists[Canciones por Playlist]) -> 150
A7: Generos | B7: Suma de Canciones por Genero | D7: Subgenero | E7: Suma de Canciones por Subgenero | G7: Playlists | H7: Suma Canciones por Playlist
A8: Electronic | B8: 148 | D8: Classic | E8: 162 | G8: EDM Hits | H8: 60
A9: Gaming | B9: 100 | D9: Modern | E9: 356 | G9: Reggaeton Hits | H9: 101
A10: Hip-Hop | B10: 227 | D10: Reggaeton | E10: 101 | G10: Rock Classics | H10: 91
A11: Latin | B11: 184 | D11: Throwback | E11: 150 | G11: Throwback Party | H11: 150
A12: Pop | B12: 357 | D12: Total general | E12: 769 | G12: Top Gaming Tracks | H12: 100
A13: Rock | B13: 235 | G13: Total general | H13: 502
A14: Total general | B14: 1251
A56: =GETPIVOTDATA("Playlist_genre2",$A$7,"Playlist_genre2","Pop") -> 357
D78: =GETPIVOTDATA("Playlist_subgenre2",$D$7,"Playlist_subgenre2","Modern") -> 356
G92: =GETPIVOTDATA("Canciones por Playlist",$G$7,"playlist_name","Throwback Party") -> 150

Sheet Respuestas Descriptivas
A1: Caracteristicas de las canciones mas escuchadas | L1: Criterios de Distribucion | V1: Volver
A4: El analisis de estos datos sobre las caracterizticas de las canciones mas escuchadas de spotify , nos permiten visulaizar tendencias en las tecnicas de produccion y composicion para poder entender mejor cuales son las variables que hacen mas popular una cancion que otra. En el caso de cuan energicas son las canciones el promedio dio relativamente alto con un 67% . Esto quiere decir que las canciones mas esuchadas son mas energeticas y dinamicas y esto hace la cancion mas bailable lo cual queda reflejado en el alto porcentaje del promedio de 65%. | L4: Despues del analisis de los criterios de distribucion de las canciones mas escuchadas , se llega a la conclusion que el Genero mas escuchado es el Pop , el Subgenero mas escuchado es el Modern y la playlist mas escuchada es Throwback Party
L7: En base al análisis de los criterios de distribución de las canciones más escuchadas, Spotify debería enfocar su estrategia en potenciar el contenido relacionado con el género Pop, especialmente su subgénero Modern, como tambien a través de playlists temáticas que evocan nostalgia como Throwback Party. Una estrategia efectiva sería crear y promocionar más listas de reproducción que combinen éxitos modernos del pop con clásicos que conecten emocionalmente con la audiencia, apuntando a públicos jóvenes adultos. Además, se recomienda utilizar campañas de marketing y colaboraciones con artistas pop contemporáneos para reforzar el posicionamiento de estas playlists.
A10: La variable Acusticness refiere a cuantos instrumentos acusticos se usaron para grabar la cancion vs cuantos instrumentos sinteticos o digitales . El promedio del procentaje de Acustica dio bastante bajo y quiere decir que hoy la tendencia es grabar canciones con sonidos digitales y sinteticos . Por Ultimo la variable valencia de una cancion nos dice cuan alegre o triste es la narrativa de una cancion . En este caso el promedio del porcentaje dio 53% que nos dice que no hay una tendencia marcada es casi la misma cantidad de canciones tristes que alegres
A17: En el caso de la variable Mode que corresponde al Modo Menor o Mayor de una cancion hay una leve tendencia a las tonalidades menores . En cuanto a las tonalidades Re bemol y Si son las tonalidades que muestran una leve ventaja en popularidad frente a las otras pero no muy significativa
C24: Conclusion Estrategica: en base al análisis de las características de las canciones más escuchadas en Spotify, se observa una clara tendencia hacia producciones energéticas, bailables y con un predominio de sonidos digitales y sintetizados. Por lo tanto, una estrategia efectiva para Spotify sería potenciar la visibilidad de canciones con alta energía y ritmo bailable dentro de sus algoritmos de recomendación y curaduría editorial, priorizando temas con producción digital. Además, al no haber una tendencia clara en cuanto a la narrativa emocional (alegre vs. triste) ni en las tonalidades, se recomienda mantener una oferta variada en estos aspectos para captar distintos perfiles emocionales de oyentes, sin enfocarse exclusivamente en un solo tono o estado de ánimo.

Sheet Anexas
A1: ID_playlist_subgenre | B1: playlist_subgenre | C1: Canciones por subgenero | I1: ID_playlist_name | J1: playlist_name | K1: Canciones por Playlist
A2: 1 | B2: 80s | C2: =COUNTIF(G30:G1687,"80s") -> 44 | I2: 1 | J2: 80s Rock Anthems | K2: =COUNTIF(TB_Music_Data!H1629:H1675,"80s Rock Anthems") -> 9
A3: 2 | B3: 90s | C3: =COUNTIF(G30:G1687,"90s") -> 19 | I3: 2 | J3: 90s Hip-Hop | K3: =COUNTIF(Music_Data[Playlist_name],"90s hip-hop") -> 19
